<?xml version="1.0" encoding="utf-8"?>
<!-- This URDF was automatically created by SolidWorks to URDF Exporter! Originally created by Stephen Brawner (brawner@gmail.com) 
     Commit Version: 1.6.0-1-g15f4949  Build Version: 1.6.7594.29634
     For more information, please see http://wiki.ros.org/sw_urdf_exporter -->
<robot
  name="NABI_angle">
  <link
    name="base_link">
    <inertial>
      <origin
        xyz="1.9621E-06 -6.2757E-07 0.62551"
        rpy="0 0 0" />
      <mass
        value="0.88263" />
      <inertia
        ixx="0.0012436"
        ixy="-1.6164E-08"
        ixz="6.6629E-08"
        iyy="0.0021092"
        iyz="-2.1311E-08"
        izz="0.0029573" />
    </inertial>
    <visual>
      <origin
        xyz="0 0 0"
        rpy="0 0 0" />
      <geometry>
        <mesh
          filename="base_link.STL" />
      </geometry>
      <material
        name="">
        <color
          rgba="0.79216 0.81961 0.93333 1" />
      </material>
    </visual>
    <collision>
      <origin
        xyz="0 0 0"
        rpy="0 0 0" />
      <geometry>
        <mesh
          filename="base_link.STL" />
      </geometry>
    </collision>
  </link>
  <link
    name="Femur1">
    <inertial>
      <origin
        xyz="-3.0676E-08 -0.00016605 -0.16171"
        rpy="0 0 0" />
      <mass
        value="0.16826" />
      <inertia
        ixx="0.0015674"
        ixy="-6.1273E-14"
        ixz="-4.1955E-11"
        iyy="0.0015674"
        iyz="-2.4904E-10"
        izz="1.3587E-05" />
    </inertial>
    <visual>
      <origin
        xyz="0 0 0"
        rpy="0 0 0" />
      <geometry>
        <mesh
          filename="Femur1.STL" />
      </geometry>
      <material
        name="">
        <color
          rgba="0.79216 0.81961 0.93333 1" />
      </material>
    </visual>
    <collision>
      <origin
        xyz="0 0 0"
        rpy="0 0 0" />
      <geometry>
        <mesh
          filename="Femur1.STL" />
      </geometry>
    </collision>
  </link>
  <joint
    name="Joint1"
    type="continuous">
    <origin
      xyz="0.05 0 0.58704"
      rpy="0 -0.7311 0" />
    <parent
      link="base_link" />
    <child
      link="Femur1" />
    <axis
      xyz="0 1 0" />
  </joint>
  <link
    name="Tibia1">
    <inertial>
      <origin
        xyz="2.059E-07 0.0027 -0.16234"
        rpy="0 0 0" />
      <mass
        value="0.1633" />
      <inertia
        ixx="0.0014323"
        ixy="-9.5339E-13"
        ixz="4.2483E-10"
        iyy="0.0014323"
        iyz="2.2888E-10"
        izz="1.3176E-05" />
    </inertial>
    <visual>
      <origin
        xyz="0 0 0"
        rpy="0 0 0" />
      <geometry>
        <mesh
          filename="Tibia1.STL" />
      </geometry>
      <material
        name="">
        <color
          rgba="0.79216 0.81961 0.93333 1" />
      </material>
    </visual>
    <collision>
      <origin
        xyz="0 0 0"
        rpy="0 0 0" />
      <geometry>
        <mesh
          filename="Tibia1.STL" />
      </geometry>
    </collision>
  </link>
  <joint
    name="Joint3"
    type="continuous">
    <origin
      xyz="0 -0.0028638 -0.33508"
      rpy="0 0.98708 0" />
    <parent
      link="Femur1" />
    <child
      link="Tibia1" />
    <axis
      xyz="0 1 0" />
  </joint>
  <link
    name="Foot1">
    <inertial>
      <origin
        xyz="0.032111 -0.014347 -0.0127"
        rpy="0 0 0" />
      <mass
        value="0.024354" />
      <inertia
        ixx="4.9617E-06"
        ixy="1.6835E-06"
        ixz="9.4771E-21"
        iyy="2.2188E-05"
        iyz="-1.3717E-21"
        izz="1.8506E-05" />
    </inertial>
    <visual>
      <origin
        xyz="0 0 0"
        rpy="0 0 0" />
      <geometry>
        <mesh
          filename="Foot1.STL" />
      </geometry>
      <material
        name="">
        <color
          rgba="0.79216 0.81961 0.93333 1" />
      </material>
    </visual>
    <collision>
      <origin
        xyz="0 0 0"
        rpy="0 0 0" />
      <geometry>
        <mesh
          filename="Foot1.STL" />
      </geometry>
    </collision>
  </link>
  <joint
    name="Joint5"
    type="continuous">
    <origin
      xyz="0 -0.01 -0.3288"
      rpy="1.5708 -0.25598 0" />
    <parent
      link="Tibia1" />
    <child
      link="Foot1" />
    <axis
      xyz="0 0 1" />
  </joint>
  <link
    name="Femur2">
    <inertial>
      <origin
        xyz="3.5111E-08 0.0127 -0.16171"
        rpy="0 0 0" />
      <mass
        value="0.16826" />
      <inertia
        ixx="0.0015674"
        ixy="1.9741E-13"
        ixz="1.145E-10"
        iyy="0.0015674"
        iyz="-2.5078E-10"
        izz="1.3587E-05" />
    </inertial>
    <visual>
      <origin
        xyz="0 0 0"
        rpy="0 0 0" />
      <geometry>
        <mesh
          filename="Femur2.STL" />
      </geometry>
      <material
        name="">
        <color
          rgba="0.79216 0.81961 0.93333 1" />
      </material>
    </visual>
    <collision>
      <origin
        xyz="0 0 0"
        rpy="0 0 0" />
      <geometry>
        <mesh
          filename="Femur2.STL" />
      </geometry>
    </collision>
  </link>
  <joint
    name="Joint2"
    type="continuous">
    <origin
      xyz="-0.05 -0.012866 0.58704"
      rpy="0 0.72939 0" />
    <parent
      link="base_link" />
    <child
      link="Femur2" />
    <axis
      xyz="0 1 0" />
  </joint>
  <link
    name="Tibia2">
    <inertial>
      <origin
        xyz="-2.093E-07 0.0027 -0.16234"
        rpy="0 0 0" />
      <mass
        value="0.1633" />
      <inertia
        ixx="0.0014323"
        ixy="6.1367E-13"
        ixz="-4.9041E-10"
        iyy="0.0014323"
        iyz="2.3922E-10"
        izz="1.3176E-05" />
    </inertial>
    <visual>
      <origin
        xyz="0 0 0"
        rpy="0 0 0" />
      <geometry>
        <mesh
          filename="Tibia2.STL" />
      </geometry>
      <material
        name="">
        <color
          rgba="0.79216 0.81961 0.93333 1" />
      </material>
    </visual>
    <collision>
      <origin
        xyz="0 0 0"
        rpy="0 0 0" />
      <geometry>
        <mesh
          filename="Tibia2.STL" />
      </geometry>
    </collision>
  </link>
  <joint
    name="Joint4"
    type="continuous">
    <origin
      xyz="0 0.010002 -0.33508"
      rpy="0 -0.98388 0" />
    <parent
      link="Femur2" />
    <child
      link="Tibia2" />
    <axis
      xyz="0 1 0" />
  </joint>
  <link
    name="Foot2">
    <inertial>
      <origin
        xyz="0.032111 -0.014347 0.0127"
        rpy="0 0 0" />
      <mass
        value="0.024354" />
      <inertia
        ixx="4.9617E-06"
        ixy="1.6835E-06"
        ixz="2.7975E-21"
        iyy="2.2188E-05"
        iyz="1.4724E-21"
        izz="1.8506E-05" />
    </inertial>
    <visual>
      <origin
        xyz="0 0 0"
        rpy="0 0 0" />
      <geometry>
        <mesh
          filename="Foot2.STL" />
      </geometry>
      <material
        name="">
        <color
          rgba="0.79216 0.81961 0.93333 1" />
      </material>
    </visual>
    <collision>
      <origin
        xyz="0 0 0"
        rpy="0 0 0" />
      <geometry>
        <mesh
          filename="Foot2.STL" />
      </geometry>
    </collision>
  </link>
  <joint
    name="Joint6"
    type="continuous">
    <origin
      xyz="0 -0.01 -0.3288"
      rpy="1.5708 -0.25449 -3.1416" />
    <parent
      link="Tibia2" />
    <child
      link="Foot2" />
    <axis
      xyz="0 0 1" />
  </joint>
</robot>